<?xml version="1.0"?>
<robot name="warehouse_bot" xmlns:xacro="http://www.ros.org/wiki/xacro">

  <!-- Base -->
  <link name="base_link">
    <visual>
      <geometry>
        <cylinder length="0.1" radius="0.15"/>
      </geometry>
    </visual>
    <collision>
      <geometry>
        <cylinder length="0.1" radius="0.15"/>
      </geometry>
    </collision>
    <inertial>
      <mass value="3.0"/>
      <origin xyz="0 0 0"/>
      <inertia ixx="0.02" iyy="0.02" izz="0.04"
               ixy="0" ixz="0" iyz="0"/>
    </inertial>
  </link>

  <!-- Wheels -->
  <link name="wheel_left_link"/>
  <link name="wheel_right_link"/>

  <joint name="wheel_left_joint" type="continuous">
    <parent link="base_link"/>
    <child link="wheel_left_link"/>
    <origin xyz="0 0.1 0"/>
    <axis xyz="0 1 0"/>
  </joint>

  <joint name="wheel_right_joint" type="continuous">
    <parent link="base_link"/>
    <child link="wheel_right_link"/>
    <origin xyz="0 -0.1 0"/>
    <axis xyz="0 1 0"/>
  </joint>

  <!-- Gazebo Diff Drive -->
  <gazebo>
    <plugin name="diff_drive" filename="libgazebo_ros_diff_drive.so">
      <left_joint>wheel_left_joint</left_joint>
      <right_joint>wheel_right_joint</right_joint>
      <wheel_separation>0.2</wheel_separation>
      <wheel_diameter>0.065</wheel_diameter>
      <cmd_vel_topic>cmd_vel</cmd_vel_topic>
      <odom_topic>odom</odom_topic>
      <publish_odom>true</publish_odom>
      <publish_odom_tf>true</publish_odom_tf>
      <robot_base_frame>base_link</robot_base_frame>
    </plugin>
  </gazebo>

</robot>
