<?xml version="1.0" ?>
<sdf version="1.9">
  <model name="turtlebot3_burger">
    <pose>0 0 0 0 0 0</pose>

    <!-- ═══════════════════════════════════════════ -->
    <!--  PLUGINS                                    -->
    <!-- ═══════════════════════════════════════════ -->
    <plugin
      filename="gz-sim-diff-drive-system"
      name="gz::sim::systems::DiffDrive">
      <left_joint>wheel_left_joint</left_joint>
      <right_joint>wheel_right_joint</right_joint>
      <wheel_separation>0.160</wheel_separation>
      <wheel_radius>0.033</wheel_radius>
      <odom_publish_frequency>30</odom_publish_frequency>
      <topic>cmd_vel</topic>
      <odom_topic>odom</odom_topic>
      <frame_id>odom</frame_id>
      <child_frame_id>base_footprint</child_frame_id>
    </plugin>

    <plugin
      filename="gz-sim-joint-state-publisher-system"
      name="gz::sim::systems::JointStatePublisher">
    </plugin>

    <!-- ═══════════════════════════════════════════ -->
    <!--  BASE                                       -->
    <!-- ═══════════════════════════════════════════ -->
    <link name="base_footprint"/>

    <joint name="base_joint" type="fixed">
      <parent>base_footprint</parent>
      <child>base_link</child>
      <pose>0 0 0.010 0 0 0</pose>
    </joint>

    <link name="base_link">
      <inertial>
        <pose>-0.064 0 0.048 0 0 0</pose>
        <inertia>
          <ixx>0.001</ixx><ixy>0.000</ixy><ixz>0.000</ixz>
          <iyy>0.001</iyy><iyz>0.000</iyz>
          <izz>0.001</izz>
        </inertia>
        <mass>1.0</mass>
      </inertial>

      <collision name="base_collision">
        <pose>-0.064 0 0.048 0 0 0</pose>
        <geometry>
          <box><size>0.140 0.140 0.143</size></box>
        </geometry>
      </collision>

      <visual name="base_visual">
        <pose>-0.064 0 0 0 0 0</pose>
        <geometry>
          <mesh>
            <uri>model://turtlebot3_burger/meshes/burger_base.dae</uri>
            <scale>0.001 0.001 0.001</scale>
          </mesh>
        </geometry>
      </visual>
    </link>

    <!-- ═══════════════════════════════════════════ -->
    <!--  WHEELS                                     -->
    <!-- ═══════════════════════════════════════════ -->
    <joint name="wheel_left_joint" type="revolute">
      <parent>base_link</parent>
      <child>wheel_left_link</child>
      <pose>0 0.080 0.023 -1.5707963 0 0</pose>
      <axis>
        <xyz>0 0 1</xyz>
        <limit><lower>-1e+16</lower><upper>1e+16</upper></limit>
      </axis>
    </joint>

    <link name="wheel_left_link">
      <inertial>
        <mass>0.1</mass>
        <inertia>
          <ixx>0.001</ixx><ixy>0.000</ixy><ixz>0.000</ixz>
          <iyy>0.001</iyy><iyz>0.000</iyz>
          <izz>0.001</izz>
        </inertia>
      </inertial>
      <collision name="wheel_left_collision">
        <geometry>
          <cylinder><radius>0.033</radius><length>0.018</length></cylinder>
        </geometry>
        <surface>
          <friction><ode><mu>100</mu><mu2>100</mu2></ode></friction>
        </surface>
      </collision>
      <visual name="wheel_left_visual">
        <geometry>
          <mesh>
            <uri>model://turtlebot3_burger/meshes/left_tire.dae</uri>
            <scale>0.001 0.001 0.001</scale>
          </mesh>
        </geometry>
      </visual>
    </link>

    <joint name="wheel_right_joint" type="revolute">
      <parent>base_link</parent>
      <child>wheel_right_link</child>
      <pose>0 -0.080 0.023 -1.5707963 0 0</pose>
      <axis>
        <xyz>0 0 1</xyz>
        <limit><lower>-1e+16</lower><upper>1e+16</upper></limit>
      </axis>
    </joint>

    <link name="wheel_right_link">
      <inertial>
        <mass>0.1</mass>
        <inertia>
          <ixx>0.001</ixx><ixy>0.000</ixy><ixz>0.000</ixz>
          <iyy>0.001</iyy><iyz>0.000</iyz>
          <izz>0.001</izz>
        </inertia>
      </inertial>
      <collision name="wheel_right_collision">
        <geometry>
          <cylinder><radius>0.033</radius><length>0.018</length></cylinder>
        </geometry>
        <surface>
          <friction><ode><mu>100</mu><mu2>100</mu2></ode></friction>
        </surface>
      </collision>
      <visual name="wheel_right_visual">
        <geometry>
          <mesh>
            <uri>model://turtlebot3_burger/meshes/right_tire.dae</uri>
            <scale>0.001 0.001 0.001</scale>
          </mesh>
        </geometry>
      </visual>
    </link>

    <!-- caster wheel -->
    <joint name="caster_back_joint" type="ball">
      <parent>base_link</parent>
      <child>caster_back_link</child>
    </joint>

    <link name="caster_back_link">
      <pose>-0.177 0 -0.005 0 0 0</pose>
      <inertial>
        <mass>0.001</mass>
        <inertia>
          <ixx>0.00001</ixx><ixy>0</ixy><ixz>0</ixz>
          <iyy>0.00001</iyy><iyz>0</iyz>
          <izz>0.00001</izz>
        </inertia>
      </inertial>
      <collision name="caster_back_collision">
        <geometry>
          <sphere><radius>0.005</radius></sphere>
        </geometry>
        <surface>
          <friction><ode><mu>0</mu><mu2>0</mu2></ode></friction>
        </surface>
      </collision>
    </link>

    <!-- ═══════════════════════════════════════════ -->
    <!--  LIDAR                                      -->
    <!-- ═══════════════════════════════════════════ -->
    <joint name="lidar_joint" type="fixed">
      <parent>base_link</parent>
      <child>base_scan</child>
      <pose>-0.032 0 0.171 0 0 0</pose>
    </joint>

    <link name="base_scan">
      <inertial>
        <mass>0.125</mass>
        <inertia>
          <ixx>0.001</ixx><ixy>0</ixy><ixz>0</ixz>
          <iyy>0.001</iyy><iyz>0</iyz>
          <izz>0.001</izz>
        </inertia>
      </inertial>

      <collision name="lidar_collision">
        <geometry>
          <cylinder><radius>0.0508</radius><length>0.055</length></cylinder>
        </geometry>
      </collision>

      <visual name="lidar_visual">
        <geometry>
          <cylinder><radius>0.0508</radius><length>0.055</length></cylinder>
        </geometry>
      </visual>

      <!-- ✅ THIS IS THE KEY PART — gpu_lidar for Gazebo Sim -->
      <sensor name="lidar" type="gpu_lidar">
        <always_on>true</always_on>
        <visualize>true</visualize>
        <update_rate>5</update_rate>
        <topic>scan</topic>
        <gz_frame_id>base_scan</gz_frame_id>
        <ray>
          <scan>
            <horizontal>
              <samples>360</samples>
              <resolution>1</resolution>
              <min_angle>0</min_angle>
              <max_angle>6.28318530718</max_angle>
            </horizontal>
          </scan>
          <range>
            <min>0.120</min>
            <max>3.5</max>
            <resolution>0.015</resolution>
          </range>
          <noise>
            <type>gaussian</type>
            <mean>0.0</mean>
            <stddev>0.01</stddev>
          </noise>
        </ray>
      </sensor>
    </link>

  </model>
</sdf>